2018-07-19 16:05:10,542 ERROR: Exception on /follow/susan [GET] [in /home/jon/PycharmProjects/microblog/venv/lib/python3.6/site-packages/flask/app.py:1761]
Traceback (most recent call last):
  File "/home/jon/PycharmProjects/microblog/venv/lib/python3.6/site-packages/flask/app.py", line 2292, in wsgi_app
    response = self.full_dispatch_request()
  File "/home/jon/PycharmProjects/microblog/venv/lib/python3.6/site-packages/flask/app.py", line 1815, in full_dispatch_request
    rv = self.handle_user_exception(e)
  File "/home/jon/PycharmProjects/microblog/venv/lib/python3.6/site-packages/flask/app.py", line 1718, in handle_user_exception
    reraise(exc_type, exc_value, tb)
  File "/home/jon/PycharmProjects/microblog/venv/lib/python3.6/site-packages/flask/_compat.py", line 35, in reraise
    raise value
  File "/home/jon/PycharmProjects/microblog/venv/lib/python3.6/site-packages/flask/app.py", line 1813, in full_dispatch_request
    rv = self.dispatch_request()
  File "/home/jon/PycharmProjects/microblog/venv/lib/python3.6/site-packages/flask/app.py", line 1799, in dispatch_request
    return self.view_functions[rule.endpoint](**req.view_args)
  File "/home/jon/PycharmProjects/microblog/venv/lib/python3.6/site-packages/flask_login/utils.py", line 261, in decorated_view
    return func(*args, **kwargs)
  File "/home/jon/PycharmProjects/microblog/venv/app/routes.py", line 112, in follow
    return redirect(url_for('user', username=username))
  File "/home/jon/PycharmProjects/microblog/venv/lib/python3.6/site-packages/flask/helpers.py", line 356, in url_for
    return appctx.app.handle_url_build_error(error, endpoint, values)
  File "/home/jon/PycharmProjects/microblog/venv/lib/python3.6/site-packages/flask/app.py", line 2061, in handle_url_build_error
    reraise(exc_type, exc_value, tb)
  File "/home/jon/PycharmProjects/microblog/venv/lib/python3.6/site-packages/flask/_compat.py", line 35, in reraise
    raise value
  File "/home/jon/PycharmProjects/microblog/venv/lib/python3.6/site-packages/flask/helpers.py", line 345, in url_for
    force_external=external)
  File "/home/jon/PycharmProjects/microblog/venv/lib/python3.6/site-packages/werkzeug/routing.py", line 1776, in build
    raise BuildError(endpoint, values, method, self)
werkzeug.routing.BuildError: Could not build url for endpoint 'user' with values ['username']. Did you mean 'users' instead?
2018-07-19 16:07:29,119 INFO: Microblog Startup [in /home/jon/PycharmProjects/microblog/venv/app/__init__.py:44]
2018-07-19 16:07:53,656 ERROR: Exception on /follow/mary [GET] [in /home/jon/PycharmProjects/microblog/venv/lib/python3.6/site-packages/flask/app.py:1761]
Traceback (most recent call last):
  File "/home/jon/PycharmProjects/microblog/venv/lib/python3.6/site-packages/flask/app.py", line 2292, in wsgi_app
    response = self.full_dispatch_request()
  File "/home/jon/PycharmProjects/microblog/venv/lib/python3.6/site-packages/flask/app.py", line 1815, in full_dispatch_request
    rv = self.handle_user_exception(e)
  File "/home/jon/PycharmProjects/microblog/venv/lib/python3.6/site-packages/flask/app.py", line 1718, in handle_user_exception
    reraise(exc_type, exc_value, tb)
  File "/home/jon/PycharmProjects/microblog/venv/lib/python3.6/site-packages/flask/_compat.py", line 35, in reraise
    raise value
  File "/home/jon/PycharmProjects/microblog/venv/lib/python3.6/site-packages/flask/app.py", line 1813, in full_dispatch_request
    rv = self.dispatch_request()
  File "/home/jon/PycharmProjects/microblog/venv/lib/python3.6/site-packages/flask/app.py", line 1799, in dispatch_request
    return self.view_functions[rule.endpoint](**req.view_args)
  File "/home/jon/PycharmProjects/microblog/venv/lib/python3.6/site-packages/flask_login/utils.py", line 261, in decorated_view
    return func(*args, **kwargs)
  File "/home/jon/PycharmProjects/microblog/venv/app/routes.py", line 112, in follow
    return redirect(url_for('user', username=username))
  File "/home/jon/PycharmProjects/microblog/venv/lib/python3.6/site-packages/flask/helpers.py", line 356, in url_for
    return appctx.app.handle_url_build_error(error, endpoint, values)
  File "/home/jon/PycharmProjects/microblog/venv/lib/python3.6/site-packages/flask/app.py", line 2061, in handle_url_build_error
    reraise(exc_type, exc_value, tb)
  File "/home/jon/PycharmProjects/microblog/venv/lib/python3.6/site-packages/flask/_compat.py", line 35, in reraise
    raise value
  File "/home/jon/PycharmProjects/microblog/venv/lib/python3.6/site-packages/flask/helpers.py", line 345, in url_for
    force_external=external)
  File "/home/jon/PycharmProjects/microblog/venv/lib/python3.6/site-packages/werkzeug/routing.py", line 1776, in build
    raise BuildError(endpoint, values, method, self)
werkzeug.routing.BuildError: Could not build url for endpoint 'user' with values ['username']. Did you mean 'users' instead?
2018-07-19 16:08:39,308 INFO: Microblog Startup [in /home/jon/PycharmProjects/microblog/venv/app/__init__.py:44]
