2018-07-09 22:22:02,497 ERROR: Exception on /edit_profile [POST] [in C:\Users\Jonathan\Anaconda3\lib\site-packages\flask\app.py:1761]
Traceback (most recent call last):
  File "C:\Users\Jonathan\Anaconda3\lib\site-packages\sqlalchemy\engine\base.py", line 1193, in _execute_context
    context)
  File "C:\Users\Jonathan\Anaconda3\lib\site-packages\sqlalchemy\engine\default.py", line 507, in do_execute
    cursor.execute(statement, parameters)
sqlite3.IntegrityError: UNIQUE constraint failed: user.username

The above exception was the direct cause of the following exception:

Traceback (most recent call last):
  File "C:\Users\Jonathan\Anaconda3\lib\site-packages\flask\app.py", line 2292, in wsgi_app
    response = self.full_dispatch_request()
  File "C:\Users\Jonathan\Anaconda3\lib\site-packages\flask\app.py", line 1815, in full_dispatch_request
    rv = self.handle_user_exception(e)
  File "C:\Users\Jonathan\Anaconda3\lib\site-packages\flask\app.py", line 1718, in handle_user_exception
    reraise(exc_type, exc_value, tb)
  File "C:\Users\Jonathan\Anaconda3\lib\site-packages\flask\_compat.py", line 35, in reraise
    raise value
  File "C:\Users\Jonathan\Anaconda3\lib\site-packages\flask\app.py", line 1813, in full_dispatch_request
    rv = self.dispatch_request()
  File "C:\Users\Jonathan\Anaconda3\lib\site-packages\flask\app.py", line 1799, in dispatch_request
    return self.view_functions[rule.endpoint](**req.view_args)
  File "C:\Users\Jonathan\Anaconda3\lib\site-packages\flask_login\utils.py", line 261, in decorated_view
    return func(*args, **kwargs)
  File "C:\Users\Jonathan\PycharmProjects\microblog\app\routes.py", line 91, in edit_profile
    db.session.commit()
  File "C:\Users\Jonathan\Anaconda3\lib\site-packages\sqlalchemy\orm\scoping.py", line 153, in do
    return getattr(self.registry(), name)(*args, **kwargs)
  File "C:\Users\Jonathan\Anaconda3\lib\site-packages\sqlalchemy\orm\session.py", line 943, in commit
    self.transaction.commit()
  File "C:\Users\Jonathan\Anaconda3\lib\site-packages\sqlalchemy\orm\session.py", line 467, in commit
    self._prepare_impl()
  File "C:\Users\Jonathan\Anaconda3\lib\site-packages\sqlalchemy\orm\session.py", line 447, in _prepare_impl
    self.session.flush()
  File "C:\Users\Jonathan\Anaconda3\lib\site-packages\sqlalchemy\orm\session.py", line 2254, in flush
    self._flush(objects)
  File "C:\Users\Jonathan\Anaconda3\lib\site-packages\sqlalchemy\orm\session.py", line 2380, in _flush
    transaction.rollback(_capture_exception=True)
  File "C:\Users\Jonathan\Anaconda3\lib\site-packages\sqlalchemy\util\langhelpers.py", line 66, in __exit__
    compat.reraise(exc_type, exc_value, exc_tb)
  File "C:\Users\Jonathan\Anaconda3\lib\site-packages\sqlalchemy\util\compat.py", line 187, in reraise
    raise value
  File "C:\Users\Jonathan\Anaconda3\lib\site-packages\sqlalchemy\orm\session.py", line 2344, in _flush
    flush_context.execute()
  File "C:\Users\Jonathan\Anaconda3\lib\site-packages\sqlalchemy\orm\unitofwork.py", line 391, in execute
    rec.execute(self)
  File "C:\Users\Jonathan\Anaconda3\lib\site-packages\sqlalchemy\orm\unitofwork.py", line 556, in execute
    uow
  File "C:\Users\Jonathan\Anaconda3\lib\site-packages\sqlalchemy\orm\persistence.py", line 177, in save_obj
    mapper, table, update)
  File "C:\Users\Jonathan\Anaconda3\lib\site-packages\sqlalchemy\orm\persistence.py", line 768, in _emit_update_statements
    execute(statement, multiparams)
  File "C:\Users\Jonathan\Anaconda3\lib\site-packages\sqlalchemy\engine\base.py", line 948, in execute
    return meth(self, multiparams, params)
  File "C:\Users\Jonathan\Anaconda3\lib\site-packages\sqlalchemy\sql\elements.py", line 269, in _execute_on_connection
    return connection._execute_clauseelement(self, multiparams, params)
  File "C:\Users\Jonathan\Anaconda3\lib\site-packages\sqlalchemy\engine\base.py", line 1060, in _execute_clauseelement
    compiled_sql, distilled_params
  File "C:\Users\Jonathan\Anaconda3\lib\site-packages\sqlalchemy\engine\base.py", line 1200, in _execute_context
    context)
  File "C:\Users\Jonathan\Anaconda3\lib\site-packages\sqlalchemy\engine\base.py", line 1413, in _handle_dbapi_exception
    exc_info
  File "C:\Users\Jonathan\Anaconda3\lib\site-packages\sqlalchemy\util\compat.py", line 203, in raise_from_cause
    reraise(type(exception), exception, tb=exc_tb, cause=cause)
  File "C:\Users\Jonathan\Anaconda3\lib\site-packages\sqlalchemy\util\compat.py", line 186, in reraise
    raise value.with_traceback(tb)
  File "C:\Users\Jonathan\Anaconda3\lib\site-packages\sqlalchemy\engine\base.py", line 1193, in _execute_context
    context)
  File "C:\Users\Jonathan\Anaconda3\lib\site-packages\sqlalchemy\engine\default.py", line 507, in do_execute
    cursor.execute(statement, parameters)
sqlalchemy.exc.IntegrityError: (sqlite3.IntegrityError) UNIQUE constraint failed: user.username [SQL: 'UPDATE user SET username=?, about_me=? WHERE user.id = ?'] [parameters: ('susan', 'I am man hear me roar!', 2)] (Background on this error at: http://sqlalche.me/e/gkpj)
2018-07-09 22:28:06,138 INFO: Microblog Startup [in C:\Users\Jonathan\PycharmProjects\microblog\app\__init__.py:44]
2018-07-09 22:28:10,684 ERROR: Exception on /edit_profile [GET] [in C:\Users\Jonathan\Anaconda3\lib\site-packages\flask\app.py:1761]
Traceback (most recent call last):
  File "C:\Users\Jonathan\Anaconda3\lib\site-packages\flask\app.py", line 2292, in wsgi_app
    response = self.full_dispatch_request()
  File "C:\Users\Jonathan\Anaconda3\lib\site-packages\flask\app.py", line 1815, in full_dispatch_request
    rv = self.handle_user_exception(e)
  File "C:\Users\Jonathan\Anaconda3\lib\site-packages\flask\app.py", line 1718, in handle_user_exception
    reraise(exc_type, exc_value, tb)
  File "C:\Users\Jonathan\Anaconda3\lib\site-packages\flask\_compat.py", line 35, in reraise
    raise value
  File "C:\Users\Jonathan\Anaconda3\lib\site-packages\flask\app.py", line 1813, in full_dispatch_request
    rv = self.dispatch_request()
  File "C:\Users\Jonathan\Anaconda3\lib\site-packages\flask\app.py", line 1799, in dispatch_request
    return self.view_functions[rule.endpoint](**req.view_args)
  File "C:\Users\Jonathan\Anaconda3\lib\site-packages\flask_login\utils.py", line 261, in decorated_view
    return func(*args, **kwargs)
  File "C:\Users\Jonathan\PycharmProjects\microblog\app\routes.py", line 87, in edit_profile
    form = EditProfileForm(current_user.username)
  File "C:\Users\Jonathan\Anaconda3\lib\site-packages\wtforms\form.py", line 212, in __call__
    return type.__call__(cls, *args, **kwargs)
  File "C:\Users\Jonathan\PycharmProjects\microblog\app\forms.py", line 39, in __init__
    super(EditProfileForm, self).__init__(*args, **kawrgs)
NameError: name 'kawrgs' is not defined
2018-07-09 22:28:40,950 INFO: Microblog Startup [in C:\Users\Jonathan\PycharmProjects\microblog\app\__init__.py:44]
2018-07-09 22:28:47,895 ERROR: Exception on /edit_profile [POST] [in C:\Users\Jonathan\Anaconda3\lib\site-packages\flask\app.py:1761]
Traceback (most recent call last):
  File "C:\Users\Jonathan\Anaconda3\lib\site-packages\flask\app.py", line 2292, in wsgi_app
    response = self.full_dispatch_request()
  File "C:\Users\Jonathan\Anaconda3\lib\site-packages\flask\app.py", line 1815, in full_dispatch_request
    rv = self.handle_user_exception(e)
  File "C:\Users\Jonathan\Anaconda3\lib\site-packages\flask\app.py", line 1718, in handle_user_exception
    reraise(exc_type, exc_value, tb)
  File "C:\Users\Jonathan\Anaconda3\lib\site-packages\flask\_compat.py", line 35, in reraise
    raise value
  File "C:\Users\Jonathan\Anaconda3\lib\site-packages\flask\app.py", line 1813, in full_dispatch_request
    rv = self.dispatch_request()
  File "C:\Users\Jonathan\Anaconda3\lib\site-packages\flask\app.py", line 1799, in dispatch_request
    return self.view_functions[rule.endpoint](**req.view_args)
  File "C:\Users\Jonathan\Anaconda3\lib\site-packages\flask_login\utils.py", line 261, in decorated_view
    return func(*args, **kwargs)
  File "C:\Users\Jonathan\PycharmProjects\microblog\app\routes.py", line 88, in edit_profile
    if form.validate_on_submit():
  File "C:\Users\Jonathan\Anaconda3\lib\site-packages\flask_wtf\form.py", line 101, in validate_on_submit
    return self.is_submitted() and self.validate()
  File "C:\Users\Jonathan\Anaconda3\lib\site-packages\wtforms\form.py", line 310, in validate
    return super(Form, self).validate(extra)
  File "C:\Users\Jonathan\Anaconda3\lib\site-packages\wtforms\form.py", line 152, in validate
    if not field.validate(self, extra):
  File "C:\Users\Jonathan\Anaconda3\lib\site-packages\wtforms\fields\core.py", line 206, in validate
    stop_validation = self._run_validation_chain(form, chain)
  File "C:\Users\Jonathan\Anaconda3\lib\site-packages\wtforms\fields\core.py", line 226, in _run_validation_chain
    validator(form, self)
  File "C:\Users\Jonathan\PycharmProjects\microblog\app\forms.py", line 44, in validate_username
    user = User.query.filter_by(username=self.usernmae.data).first()
AttributeError: 'EditProfileForm' object has no attribute 'usernmae'
2018-07-09 22:29:22,008 INFO: Microblog Startup [in C:\Users\Jonathan\PycharmProjects\microblog\app\__init__.py:44]
2018-07-14 10:55:52,515 INFO: Microblog Startup [in C:\Users\Jonathan\PycharmProjects\microblog\app\__init__.py:44]
2018-07-14 10:56:49,281 INFO: Microblog Startup [in C:\Users\Jonathan\PycharmProjects\microblog\app\__init__.py:44]
